Workbook
Name Fore: #REF!
Name Fore: #REF!
Name Fore: #REF!
Name Fore: #REF!
Name Fore: #REF!
Name Fore: #REF!
Name Fore: #REF!
Name Fore: #REF!
Name Fore: #REF!
Name Fore: #REF!
Name Fore: #REF!
Name Fore: #REF!
Name Fore: #REF!
Name Fore: #REF!
Name Fore: #REF!
Name OLE_LINK11: Readme_Part_2!$B$61
Name OLE_LINK6: Readme_Intro!$B$44
Name Parmtype: #REF!
Name Parmtype: #REF!
Name Parmtype: #REF!
Name Parmtype: policy_parameters_uniformity!#REF!
Name Parmtype: policy_parameters_comprehensive!#REF!
Name Sheet: #REF!
Name Sheet: #REF!
Name Sheet: #REF!
Name Sheet: policy_parameters_uniformity!#REF!
Name Sheet: policy_parameters_comprehensive!#REF!

Sheet Readme_Intro
A1: Contents
B2: Part 1: Parameters defining tax rates and other general policy choices
C3: A. Introduction
C4: B. Sheets provided (links included in Readme_Part_1)
D5: Sheets formatted for user input
E6: policy_parameters.Current_law_C
E7: policy_parameters.Current_law_U
E8: csv_selection
D9: Sheets formatted to create a csv file for the model to use
E10: policy_parameters_comprehensive
E11: policy_parameters_uniformity
C12: C. How to estimate parameter values that are consistent with the uniformity perspective
C13: D. How to create alternative csv files for Part 1 parameters
B14: Part 2: Parameters defining depreciation rules, investment tax credit rules, production tax credit rules, and marginal tax rate adjustments
C15: A. Introduction
C16: B. Sheets provided (links included in Readme_Part_2.x.y)
D17: Part_2.1.1: Multi-year depreciation parameters
E18: recovery_periods_ | H18: one sheet
E19: acceleration_rates_ | H19: one sheet
E20: straight_line_flags_ | H20: one sheet
E21: inflation_adjustments_ | H21: one sheet
E22: IRS asset class mapping | H22: documentation only: not for csv
D23: Part_2.1.2: Expensing parameters
E24: sec_179_expens_shares_ | H24: three sheets
E25: other_expens_shares_ | H25: two sheets
D26: Part_2.2: Investment tax credit parameters
E27: itc_rates_ | H27: two sheets
E28: itc_nondeprcbl_bases_ | H28: one sheet
D29: Part_2.3: Production tax credit parameters
E30: ptc_rates_ | H30: nine sheets
D31: Part_2.4: Marginal_tax rate adjustment parameters
E32: sec_199A_adjustments_ | H32: one sheet
E33: industry_adjustments_ | H33: one sheet
E34: asset_adjustments_ | H34: one sheet
E35: Interaction check | H35: utility only: not for csv
C36: C. Part 2 worksheet naming conventions
C37: D. Guide to color-coding in Part 2 worksheets
C38: E. How to estimate parameter values that are consistent with the uniformity perspective
C39: F. How to create alternative csv files for Part 2 parameters

Sheet Readme_Part_1
A1: Part 1: Parameters defining tax rates and other general policy choices
B3: A. Introduction
C4: Parameters in Part 1 vary by year. The sheets provided contain current law values from 2026 through 2036.
C5: ▪ | D5: To see the list of sheets provided, click here.
C6: Most of the parameters are numerical values, such as tax rates, but one set of parameters (rows 49-67) contains character values that tell the model which parameter files to use from Part 2. The Readme files for Part 2 will explain how to select values for those parameters. The model expects two .csv files--one containing parameter values consistent with the comprehensive perspective, and one containing parameter values consistent with the uniformity perspective.
C7: ▪ | D7: For guidance on how to make parameter values consistent with the uniformity perspective, click here.
C8: ▪ | D8: For guidance on how to create the two .csv files, click here.
B10: B. Sheets provided (consistent with CBO's Winter 2026 baseline)
B12: · Sheets formatted for user input
C13: policy_parameters.Current_law_C
D14: This sheet contains policy parameter values that are consistent with current law under the comprehensive analytical perspective.
C15: policy_parameters.Current_law_U
D16: This sheet contains the same policy parameters as the comprehensive sheet, but the values are consistent with the tax uniformity analytical perspective. Values that differ from the comprehensive sheet are rendered in dark red.
C17: csv_selection
D18: Use this sheet to select which of the available policy_parameter sheets to write as .csv files for the model to use.
B20: · Sheets formatted to generate a .csv file for the model to use
C21: policy_parameters_comprehensive
C22: policy_parameters_uniformity
D23: Do not make changes to the cells in these sheets. Doing so will break the links with sheets formatted for user input. If you want to make changes directly to a .csv file, read that .csv file into Excel, make the changes, and save it.
B25: C. How to estimate parameter values that are consistent with the uniformity perspective
B27: The uniformity perspective is intended to illuminate differences in tax treatment among different industries, asset types, legal forms of organization, and sources of financing. Under the comprehensive perspective, however, some parameter values differ for other reasons. Among Part 1 parameters, those fall into three categories:
B28: 1. | C28: Marginal individual income tax rates. Under the comprehensive perspective, individual income tax rates that apply to different sources of income or deductions reflect the circumstances (specifically, the taxable income from all sources) of the recipients of that income or claimants of those deductions. Because each source of income is distributed differently across the income scale, each source will face a different average marginal tax rate. Under the uniformity perspective, however, individual income tax rates should be independent of the circumstances of the recipients and claimants. Any differences should reflect only differences in the tax law. Under current law, CBO recognizes only four distinct categories of individual income tax rates that are defined solely by the tax law. The following table lists the four categories, the income sources and deductions that belong to each, and 2025 values under each perspective as an illustration:
D30: Income source | F30: 2026 value under the comprehensive perspective | H30: 2026 value under the uniformity perspective
C31: a. | D31: Capital gains held until death | F31: 0 | H31: 0
C32: b. | D32: Income from nontaxable retirement accounts | F32: 0 | H32: 0
C33: c. | D33: Income subject to a 20% maximum rate
D34: Dividends | F34: 0.1997 | H34: 0.2092
D35: Long-term capital gains | F35: 0.2116 | H35: 0.2092
C36: d. | D36: Income and deductions subject to the ordinary rate schedule
D37: Profits from pass-through businesses | F37: 0.3042 | H37: 0.2776
D38: Interest | F38: 0.3036 | H38: 0.2776
D39: Short-term capital gains | F39: 0.3495 | H39: 0.2776
D40: Income from temporarily tax-deferred accounts | F40: 0.231 | H40: 0.2776
D41: Home mortgage interest deductions | F41: 0.1949 | H41: 0.2776
D42: Homeowner property tax deductions | F42: 0.1776 | H42: 0.2776
C43: For category c, CBO calculated an average rate using (1 -c_corp_equity_retained_earnings_share)*(1-c_corp_equity_repurchases_share) as the weight on dividends and 1 minus that share as the weight on long-term capital gains. For category d, CBO calculated an average rate from interest (weighted by the share of marginal investment financed by debt) and short-term capital gains (weighted by the share of marginal investment financed by equity).
C44: You are not bound by the groupings in the above table. You can group sources however you like as long as the groupings are driven by explicit policy choices, not by correlations.
B46: 2. | C46: Business interest deduction limitations: The limitations on the deductibility of business interest expenses apply only above certain gross receipts thresholds. Because of their size, many more C corporations are subject to those limitations than are pass-through entities. Therefore, under the comprehensive perspective, the deductible share of C corporation interest is lower than that for pass-through entities. That difference, however, is driven by the average business size, not the tax law. Thus, under the uniformity perspective, CBO used an average deductible share for both organizational forms using each form’s share of interest paid as the weights.
D47: Legal form of organization | F47: 2026 value under the comprehensive perspective | H47: 2026 value under the uniformity perspective
D48: C Corporations | F48: 0.9884 | H48: 0.9888
...

Sheet policy_parameters.Current_law_C
A1: Variable names from working paper | C1: Variable names in csv file | D1: Template for policy parameter values under the comprehensive perspective
C2: year | D2: 2026 | E2: 2027 | F2: 2028 | G2: 2029 | H2: 2030 | I2: 2031 | J2: 2032 | K2: 2033 | L2: 2034 | M2: 2035 | N2: 2036
A3: Tax Rate Parameters
B4: Taxes on profits/imputed rent
A5: t[cc] | C5: c_corp_tax_rate | D5: 0.21 | E5: 0.21 | F5: 0.21 | G5: 0.21 | H5: 0.21 | I5: 0.21 | J5: 0.21 | K5: 0.21 | L5: 0.21 | M5: 0.21 | N5: 0.21
A6: t[pt] | C6: pass_thru_tax_rate | D6: 0.3042 | E6: 0.3056 | F6: 0.3051 | G6: 0.3103 | H6: 0.3121 | I6: 0.312 | J6: 0.3121 | K6: 0.3123 | L6: 0.3139 | M6: 0.3139 | N6: 0.3164
A7: t[se] | C7: seca_tax_rate | D7: 0.0352 | E7: 0.0352 | F7: 0.0352 | G7: 0.0352 | H7: 0.0352 | I7: 0.0352 | J7: 0.0352 | K7: 0.0352 | L7: 0.0352 | M7: 0.0353 | N7: 0.0353
A8: t[rep] | C8: repurchases_tax_rate | D8: 0.01 | E8: 0.01 | F8: 0.01 | G8: 0.01 | H8: 0.01 | I8: 0.01 | J8: 0.01 | K8: 0.01 | L8: 0.01 | M8: 0.01 | N8: 0.01
A9: t[oh] | C9: ooh_tax_rate | D9: 0 | E9: 0 | F9: 0 | G9: 0 | H9: 0 | I9: 0 | J9: 0 | K9: 0 | L9: 0 | M9: 0 | N9: 0
B10: Individual income taxes on investment income
A11: t[div] | C11: dividend_inc_tax_rate | D11: 0.1997 | E11: 0.1999 | F11: 0.2006 | G11: 0.1968 | H11: 0.1991 | I11: 0.2 | J11: 0.2018 | K11: 0.2003 | L11: 0.2022 | M11: 0.2019 | N11: 0.2063
A12: t[scg] | C12: cap_gains_short_term_tax_rate | D12: 0.3495 | E12: 0.3445 | F12: 0.3409 | G12: 0.3347 | H12: 0.3331 | I12: 0.3322 | J12: 0.33 | K12: 0.3308 | L12: 0.332 | M12: 0.3317 | N12: 0.3339
A13: t[lcg] | C13: cap_gains_long_term_tax_rate | D13: 0.2116 | E13: 0.2095 | F13: 0.2072 | G13: 0.2051 | H13: 0.2041 | I13: 0.2038 | J13: 0.2042 | K13: 0.2046 | L13: 0.2049 | M13: 0.2042 | N13: 0.2052
A14: t[xcg] | C14: cap_gains_at_death_tax_rate | D14: 0 | E14: 0 | F14: 0 | G14: 0 | H14: 0 | I14: 0 | J14: 0 | K14: 0 | L14: 0 | M14: 0 | N14: 0
A15: t[int,cc] | C15: interest_inc_from_biz_tax_rate | D15: 0.3036 | E15: 0.3044 | F15: 0.3045 | G15: 0.3041 | H15: 0.3064 | I15: 0.3056 | J15: 0.3041 | K15: 0.3064 | L15: 0.3056 | M15: 0.3061 | N15: 0.3089
A16: t[int,oh] | C16: interest_inc_from_ooh_tax_rate | D16: 0.3036 | E16: 0.3044 | F16: 0.3045 | G16: 0.3041 | H16: 0.3064 | I16: 0.3056 | J16: 0.3041 | K16: 0.3064 | L16: 0.3056 | M16: 0.3061 | N16: 0.3089
A17: t[td] | C17: ret_plan_deferred_tax_rate | D17: 0.231 | E17: 0.2308 | F17: 0.2339 | G17: 0.2311 | H17: 0.2331 | I17: 0.2341 | J17: 0.2359 | K17: 0.2381 | L17: 0.2364 | M17: 0.2379 | N17: 0.238
A18: t[nt] | C18: ret_plan_nontaxable_tax_rate | D18: 0 | E18: 0 | F18: 0 | G18: 0 | H18: 0 | I18: 0 | J18: 0 | K18: 0 | L18: 0 | M18: 0 | N18: 0
B19: Individual income taxes that apply to itemized deductions
A20: t[hmi] | C20: mortg_interest_deduction_tax_rate | D20: 0.1949 | E20: 0.1947 | F20: 0.1943 | G20: 0.1976 | H20: 0.1978 | I20: 0.1978 | J20: 0.1983 | K20: 0.1988 | L20: 0.1996 | M20: 0.2006 | N20: 0.2015
A21: t[ptx] | C21: prop_tax_deduction_tax_rate | D21: 0.1776 | E21: 0.1778 | F21: 0.1774 | G21: 0.1817 | H21: 0.1816 | I21: 0.1814 | J21: 0.1816 | K21: 0.1818 | L21: 0.1823 | M21: 0.1828 | N21: 0.1836
A22: Deduction Parameters
A23: ξ | C23: pass_thru_inc_share_below_thresholds | D23: 0.3225 | E23: 0.318 | F23: 0.3209 | G23: 0.3133 | H23: 0.305 | I23: 0.3035 | J23: 0.3006 | K23: 0.2979 | L23: 0.2948 | M23: 0.2919 | N23: 0.2896
A24: q^ | C24: pass_thru_eligibility_below_thresholds | D24: 0.7734 | E24: 0.7741 | F24: 0.7749 | G24: 0.775 | H24: 0.7743 | I24: 0.7744 | J24: 0.774 | K24: 0.7738 | L24: 0.7739 | M24: 0.7732 | N24: 0.773
A25: θ[cc] | C25: c_corp_interest_deductible_share | D25: 0.9884 | E25: 0.9815 | F25: 0.9768 | G25: 0.9739 | H25: 0.9724 | I25: 0.9723 | J25: 0.9727 | K25: 0.9733 | L25: 0.9736 | M25: 0.9738 | N25: 0.9743
A26: θ[pt] | C26: pass_thru_interest_deductible_share | D26: 0.9933 | E26: 0.9894 | F26: 0.9867 | G26: 0.985 | H26: 0.9841 | I26: 0.9841 | J26: 0.9842 | K26: 0.9846 | L26: 0.9848 | M26: 0.9849 | N26: 0.9852
A27: θ[oh] | C27: mortg_interest_deductible_share | D27: 0.5552 | E27: 0.5876 | F27: 0.6222 | G27: 0.6473 | H27: 0.5526 | I27: 0.5723 | J27: 0.589 | K27: 0.6036 | L27: 0.6137 | M27: 0.6211 | N27: 0.6253
A28: λ | C28: prop_tax_deductible_share | D28: 0.3457 | E28: 0.356 | F28: 0.3709 | G28: 0.3781 | H28: 0.0435 | I28: 0.0436 | J28: 0.0424 | K28: 0.0413 | L28: 0.04 | M28: 0.0383 | N28: 0.0365
A29: Timing Adjustment Parameters Reflecting Fluctuating Rates of Return
B30: Ratio of PV of item to nominal item
A31: ν[cc,inc] | C31: c_corp_net_inc_timing_adjustment | D31: 1 | E31: 1 | F31: 1 | G31: 1 | H31: 1 | I31: 1 | J31: 1 | K31: 1 | L31: 1 | M31: 1 | N31: 1
A32: ν[pt,inc] | C32: pass_thru_net_inc_timing_adjustment | D32: 1 | E32: 1 | F32: 1 | G32: 1 | H32: 1 | I32: 1 | J32: 1 | K32: 1 | L32: 1 | M32: 1 | N32: 1
A33: ν[se,inc] | C33: seca_net_inc_timing_adjustment | D33: 1 | E33: 1 | F33: 1 | G33: 1 | H33: 1 | I33: 1 | J33: 1 | K33: 1 | L33: 1 | M33: 1 | N33: 1
A34: ν[cc,ded] | C34: c_corp_deductions_timing_adjustment | D34: 1 | E34: 1 | F34: 1 | G34: 1 | H34: 1 | I34: 1 | J34: 1 | K34: 1 | L34: 1 | M34: 1 | N34: 1
A35: ν[pt,ded] | C35: pass_thru_deductions_timing_adjustment | D35: 1 | E35: 1 | F35: 1 | G35: 1 | H35: 1 | I35: 1 | J35: 1 | K35: 1 | L35: 1 | M35: 1 | N35: 1
A36: ν[se,ded] | C36: seca_deductions_timing_adjustment | D36: 1 | E36: 1 | F36: 1 | G36: 1 | H36: 1 | I36: 1 | J36: 1 | K36: 1 | L36: 1 | M36: 1 | N36: 1
A37: ν[cc,crd] | C37: c_corp_credits_timing_adjustment | D37: 1 | E37: 1 | F37: 1 | G37: 1 | H37: 1 | I37: 1 | J37: 1 | K37: 1 | L37: 1 | M37: 1 | N37: 1
A38: ν[pt,crd] | C38: pass_thru_credits_timing_adjustment | D38: 1 | E38: 1 | F38: 1 | G38: 1 | H38: 1 | I38: 1 | J38: 1 | K38: 1 | L38: 1 | M38: 1 | N38: 1
A39: Additive Annual Changes to Holding Period Parameters
A40: ω[stg] Δ | C40: change_cap_gains_short_term_share | D40: 0 | E40: 0 | F40: 0 | G40: 0 | H40: 0 | I40: 0 | J40: 0 | K40: 0 | L40: 0 | M40: 0 | N40: 0
...

Sheet policy_parameters.Current_law_U
A1: Variable names from working paper | C1: Variable names in csv file | D1: Template for policy parameter values under the uniformity perspective
C2: year | D2: 2026 | E2: 2027 | F2: 2028 | G2: 2029 | H2: 2030 | I2: 2031 | J2: 2032 | K2: 2033 | L2: 2034 | M2: 2035 | N2: 2036
A3: Tax Rate Parameters
B4: Taxes on profits/imputed rent
A5: t[cc] | C5: c_corp_tax_rate | D5: 0.21 | E5: 0.21 | F5: 0.21 | G5: 0.21 | H5: 0.21 | I5: 0.21 | J5: 0.21 | K5: 0.21 | L5: 0.21 | M5: 0.21 | N5: 0.21
A6: t[pt] | C6: pass_thru_tax_rate | D6: 0.2776 | E6: 0.2769 | F6: 0.2759 | G6: 0.276 | H6: 0.2766 | I6: 0.276 | J6: 0.275 | K6: 0.2761 | L6: 0.2764 | M6: 0.2767 | N6: 0.2787
A7: t[se] | C7: seca_tax_rate | D7: 0.0352 | E7: 0.0352 | F7: 0.0352 | G7: 0.0352 | H7: 0.0352 | I7: 0.0352 | J7: 0.0352 | K7: 0.0352 | L7: 0.0352 | M7: 0.0353 | N7: 0.0353
A8: t[rep] | C8: repurchases_tax_rate | D8: 0.01 | E8: 0.01 | F8: 0.01 | G8: 0.01 | H8: 0.01 | I8: 0.01 | J8: 0.01 | K8: 0.01 | L8: 0.01 | M8: 0.01 | N8: 0.01
A9: t[oh] | C9: ooh_tax_rate | D9: 0 | E9: 0 | F9: 0 | G9: 0 | H9: 0 | I9: 0 | J9: 0 | K9: 0 | L9: 0 | M9: 0 | N9: 0
B10: Individual income taxes on investment income
A11: t[div] | C11: dividend_inc_tax_rate | D11: 0.2092 | E11: 0.2076 | F11: 0.2059 | G11: 0.2034 | H11: 0.2031 | I11: 0.203 | J11: 0.2037 | K11: 0.2037 | L11: 0.2044 | M11: 0.2037 | N11: 0.2054
A12: t[scg] | C12: cap_gains_short_term_tax_rate | D12: 0.2776 | E12: 0.2769 | F12: 0.2759 | G12: 0.276 | H12: 0.2766 | I12: 0.276 | J12: 0.275 | K12: 0.2761 | L12: 0.2764 | M12: 0.2767 | N12: 0.2787
A13: t[lcg] | C13: cap_gains_long_term_tax_rate | D13: 0.2092 | E13: 0.2076 | F13: 0.2059 | G13: 0.2034 | H13: 0.2031 | I13: 0.203 | J13: 0.2037 | K13: 0.2037 | L13: 0.2044 | M13: 0.2037 | N13: 0.2054
A14: t[xcg] | C14: cap_gains_at_death_tax_rate | D14: 0 | E14: 0 | F14: 0 | G14: 0 | H14: 0 | I14: 0 | J14: 0 | K14: 0 | L14: 0 | M14: 0 | N14: 0
A15: t[int,cc] | C15: interest_inc_from_biz_tax_rate | D15: 0.2776 | E15: 0.2769 | F15: 0.2759 | G15: 0.276 | H15: 0.2766 | I15: 0.276 | J15: 0.275 | K15: 0.2761 | L15: 0.2764 | M15: 0.2767 | N15: 0.2787
A16: t[int,oh] | C16: interest_inc_from_ooh_tax_rate | D16: 0.2776 | E16: 0.2769 | F16: 0.2759 | G16: 0.276 | H16: 0.2766 | I16: 0.276 | J16: 0.275 | K16: 0.2761 | L16: 0.2764 | M16: 0.2767 | N16: 0.2787
A17: t[td] | C17: ret_plan_deferred_tax_rate | D17: 0.2776 | E17: 0.2769 | F17: 0.2759 | G17: 0.276 | H17: 0.2766 | I17: 0.276 | J17: 0.275 | K17: 0.2761 | L17: 0.2764 | M17: 0.2767 | N17: 0.2787
A18: t[nt] | C18: ret_plan_nontaxable_tax_rate | D18: 0 | E18: 0 | F18: 0 | G18: 0 | H18: 0 | I18: 0 | J18: 0 | K18: 0 | L18: 0 | M18: 0 | N18: 0
B19: Individual income taxes that apply to itemized deductions
A20: t[hmi] | C20: mortg_interest_deduction_tax_rate | D20: 0.2776 | E20: 0.2769 | F20: 0.2759 | G20: 0.276 | H20: 0.2766 | I20: 0.276 | J20: 0.275 | K20: 0.2761 | L20: 0.2764 | M20: 0.2767 | N20: 0.2787
A21: t[ptx] | C21: prop_tax_deduction_tax_rate | D21: 0.2776 | E21: 0.2769 | F21: 0.2759 | G21: 0.276 | H21: 0.2766 | I21: 0.276 | J21: 0.275 | K21: 0.2761 | L21: 0.2764 | M21: 0.2767 | N21: 0.2787
A22: Deduction Parameters
A23: ξ | C23: pass_thru_inc_share_below_thresholds | D23: 0.3225 | E23: 0.318 | F23: 0.3209 | G23: 0.3133 | H23: 0.305 | I23: 0.3035 | J23: 0.3006 | K23: 0.2979 | L23: 0.2948 | M23: 0.2919 | N23: 0.2896
A24: q^ | C24: pass_thru_eligibility_below_thresholds | D24: 0.7734 | E24: 0.7741 | F24: 0.7749 | G24: 0.775 | H24: 0.7743 | I24: 0.7744 | J24: 0.774 | K24: 0.7738 | L24: 0.7739 | M24: 0.7732 | N24: 0.773
A25: θ[cc] | C25: c_corp_interest_deductible_share | D25: 0.9888 | E25: 0.9822 | F25: 0.9777 | G25: 0.9749 | H25: 0.9734 | I25: 0.9734 | J25: 0.9737 | K25: 0.9743 | L25: 0.9746 | M25: 0.9748 | N25: 0.9753
A26: θ[pt] | C26: pass_thru_interest_deductible_share | D26: 0.9888 | E26: 0.9822 | F26: 0.9777 | G26: 0.9749 | H26: 0.9734 | I26: 0.9734 | J26: 0.9737 | K26: 0.9743 | L26: 0.9746 | M26: 0.9748 | N26: 0.9753
A27: θ[oh] | C27: mortg_interest_deductible_share | D27: 0.5552 | E27: 0.5876 | F27: 0.6222 | G27: 0.6473 | H27: 0.5526 | I27: 0.5723 | J27: 0.589 | K27: 0.6036 | L27: 0.6137 | M27: 0.6211 | N27: 0.6253
A28: λ | C28: prop_tax_deductible_share | D28: 0.3457 | E28: 0.356 | F28: 0.3709 | G28: 0.3781 | H28: 0.0435 | I28: 0.0436 | J28: 0.0424 | K28: 0.0413 | L28: 0.04 | M28: 0.0383 | N28: 0.0365
A29: Timing Adjustment Parameters Reflecting Fluctuating Rates of Return
B30: Ratio of PV of item to nominal item
A31: ν[cc,inc] | C31: c_corp_net_inc_timing_adjustment | D31: 1 | E31: 1 | F31: 1 | G31: 1 | H31: 1 | I31: 1 | J31: 1 | K31: 1 | L31: 1 | M31: 1 | N31: 1
A32: ν[pt,inc] | C32: pass_thru_net_inc_timing_adjustment | D32: 1 | E32: 1 | F32: 1 | G32: 1 | H32: 1 | I32: 1 | J32: 1 | K32: 1 | L32: 1 | M32: 1 | N32: 1
A33: ν[se,inc] | C33: seca_net_inc_timing_adjustment | D33: 1 | E33: 1 | F33: 1 | G33: 1 | H33: 1 | I33: 1 | J33: 1 | K33: 1 | L33: 1 | M33: 1 | N33: 1
A34: ν[cc,ded] | C34: c_corp_deductions_timing_adjustment | D34: 1 | E34: 1 | F34: 1 | G34: 1 | H34: 1 | I34: 1 | J34: 1 | K34: 1 | L34: 1 | M34: 1 | N34: 1
A35: ν[pt,ded] | C35: pass_thru_deductions_timing_adjustment | D35: 1 | E35: 1 | F35: 1 | G35: 1 | H35: 1 | I35: 1 | J35: 1 | K35: 1 | L35: 1 | M35: 1 | N35: 1
A36: ν[se,ded] | C36: seca_deductions_timing_adjustment | D36: 1 | E36: 1 | F36: 1 | G36: 1 | H36: 1 | I36: 1 | J36: 1 | K36: 1 | L36: 1 | M36: 1 | N36: 1
A37: ν[cc,crd] | C37: c_corp_credits_timing_adjustment | D37: 1 | E37: 1 | F37: 1 | G37: 1 | H37: 1 | I37: 1 | J37: 1 | K37: 1 | L37: 1 | M37: 1 | N37: 1
A38: ν[pt,crd] | C38: pass_thru_credits_timing_adjustment | D38: 1 | E38: 1 | F38: 1 | G38: 1 | H38: 1 | I38: 1 | J38: 1 | K38: 1 | L38: 1 | M38: 1 | N38: 1
A39: Additive Annual Changes to Holding Period Parameters
A40: ω[stg] Δ | C40: change_cap_gains_short_term_share | D40: 0 | E40: 0 | F40: 0 | G40: 0 | H40: 0 | I40: 0 | J40: 0 | K40: 0 | L40: 0 | M40: 0 | N40: 0
...

Sheet csv_selection
A1: Comprehensive perspective | B1: policy_parameters. | C1: Current_law_C
A2: Uniformity perspective | B2: policy_parameters. | C2: Current_law_U
C4: Enter suffixes of policy_parameters files in cells C1 and C2

Sheet policy_parameters_comprehensive
A1: =INDIRECT(csv_selection!$B$1 & csv_selection!$C$1 & "!C2") -> year | B1: =INDIRECT(csv_selection!$B$1 & csv_selection!$C$1 & "!C5") -> c_corp_tax_rate | C1: =INDIRECT(csv_selection!$B$1 & csv_selection!$C$1 & "!C6") -> pass_thru_tax_rate | D1: =INDIRECT(csv_selection!$B$1 & csv_selection!$C$1 & "!C7") -> seca_tax_rate | E1: =INDIRECT(csv_selection!$B$1 & csv_selection!$C$1 & "!C8") -> repurchases_tax_rate | F1: =INDIRECT(csv_selection!$B$1 & csv_selection!$C$1 & "!C9") -> ooh_tax_rate | G1: =INDIRECT(csv_selection!$B$1 & csv_selection!$C$1 & "!C11") -> dividend_inc_tax_rate | H1: =INDIRECT(csv_selection!$B$1 & csv_selection!$C$1 & "!C12") -> cap_gains_short_term_tax_rate | I1: =INDIRECT(csv_selection!$B$1 & csv_selection!$C$1 & "!C13") -> cap_gains_long_term_tax_rate | J1: =INDIRECT(csv_selection!$B$1 & csv_selection!$C$1 & "!C14") -> cap_gains_at_death_tax_rate | K1: =INDIRECT(csv_selection!$B$1 & csv_selection!$C$1 & "!C15") -> interest_inc_from_biz_tax_rate | L1: =INDIRECT(csv_selection!$B$1 & csv_selection!$C$1 & "!C16") -> interest_inc_from_ooh_tax_rate | M1: =INDIRECT(csv_selection!$B$1 & csv_selection!$C$1 & "!C17") -> ret_plan_deferred_tax_rate | N1: =INDIRECT(csv_selection!$B$1 & csv_selection!$C$1 & "!C18") -> ret_plan_nontaxable_tax_rate | O1: =INDIRECT(csv_selection!$B$1 & csv_selection!$C$1 & "!C20") -> mortg_interest_deduction_tax_rate | P1: =INDIRECT(csv_selection!$B$1 & csv_selection!$C$1 & "!C21") -> prop_tax_deduction_tax_rate | Q1: =INDIRECT(csv_selection!$B$1 & csv_selection!$C$1 & "!C23") -> pass_thru_inc_share_below_thresholds | R1: =INDIRECT(csv_selection!$B$1 & csv_selection!$C$1 & "!C24") -> pass_thru_eligibility_below_thresholds | S1: =INDIRECT(csv_selection!$B$1 & csv_selection!$C$1 & "!C25") -> c_corp_interest_deductible_share | T1: =INDIRECT(csv_selection!$B$1 & csv_selection!$C$1 & "!C26") -> pass_thru_interest_deductible_share | U1: =INDIRECT(csv_selection!$B$1 & csv_selection!$C$1 & "!C27") -> mortg_interest_deductible_share | V1: =INDIRECT(csv_selection!$B$1 & csv_selection!$C$1 & "!C28") -> prop_tax_deductible_share | W1: =INDIRECT(csv_selection!$B$1 & csv_selection!$C$1 & "!C31") -> c_corp_net_inc_timing_adjustment | X1: =INDIRECT(csv_selection!$B$1 & csv_selection!$C$1 & "!C32") -> pass_thru_net_inc_timing_adjustment | Y1: =INDIRECT(csv_selection!$B$1 & csv_selection!$C$1 & "!C33") -> seca_net_inc_timing_adjustment | Z1: =INDIRECT(csv_selection!$B$1 & csv_selection!$C$1 & "!C34") -> c_corp_deductions_timing_adjustment | AA1: =INDIRECT(csv_selection!$B$1 & csv_selection!$C$1 & "!C35") -> pass_thru_deductions_timing_adjustment | AB1: =INDIRECT(csv_selection!$B$1 & csv_selection!$C$1 & "!C36") -> seca_deductions_timing_adjustment | AC1: =INDIRECT(csv_selection!$B$1 & csv_selection!$C$1 & "!C37") -> c_corp_credits_timing_adjustment | AD1: =INDIRECT(csv_selection!$B$1 & csv_selection!$C$1 & "!C38") -> pass_thru_credits_timing_adjustment | AE1: =INDIRECT(csv_selection!$B$1 & csv_selection!$C$1 & "!C40") -> change_cap_gains_short_term_share | AF1: =INDIRECT(csv_selection!$B$1 & csv_selection!$C$1 & "!C41") -> change_cap_gains_at_death_share | AG1: =INDIRECT(csv_selection!$B$1 & csv_selection!$C$1 & "!C42") -> change_cap_gains_short_term_holding_period | AH1: =INDIRECT(csv_selection!$B$1 & csv_selection!$C$1 & "!C43") -> change_cap_gains_long_term_holding_period | AI1: =INDIRECT(csv_selection!$B$1 & csv_selection!$C$1 & "!C44") -> change_cap_gains_at_death_holding_period | AJ1: =INDIRECT(csv_selection!$B$1 & csv_selection!$C$1 & "!C45") -> change_ret_plan_deferred_holding_period | AK1: =INDIRECT(csv_selection!$B$1 & csv_selection!$C$1 & "!C46") -> change_ret_plan_nontaxable_holding_period | AL1: =INDIRECT(csv_selection!$B$1 & csv_selection!$C$1 & "!C47") -> change_inventories_holding_period | AM1: =INDIRECT(csv_selection!$B$1 & csv_selection!$C$1 & "!C50") -> recovery_periods | AN1: =INDIRECT(csv_selection!$B$1 & csv_selection!$C$1 & "!C51") -> acceleration_rates | AO1: =INDIRECT(csv_selection!$B$1 & csv_selection!$C$1 & "!C52") -> straight_line_flags | AP1: =INDIRECT(csv_selection!$B$1 & csv_selection!$C$1 & "!C53") -> inflation_adjustments | AQ1: =INDIRECT(csv_selection!$B$1 & csv_selection!$C$1 & "!C54") -> c_corp_sec_179_expens_shares | AR1: =INDIRECT(csv_selection!$B$1 & csv_selection!$C$1 & "!C55") -> pass_thru_sec_179_expens_shares | AS1: =INDIRECT(csv_selection!$B$1 & csv_selection!$C$1 & "!C56") -> other_expens_shares | AT1: =INDIRECT(csv_selection!$B$1 & csv_selection!$C$1 & "!C58") -> itc_rates | AU1: =INDIRECT(csv_selection!$B$1 & csv_selection!$C$1 & "!C59") -> itc_nondeprcbl_bases | AV1: =INDIRECT(csv_selection!$B$1 & csv_selection!$C$1 & "!C61") -> ptc_rates | AW1: =INDIRECT(csv_selection!$B$1 & csv_selection!$C$1 & "!C63") -> sec_199A_adjustments | AX1: =INDIRECT(csv_selection!$B$1 & csv_selection!$C$1 & "!C64") -> c_corp_industry_adjustments | AY1: =INDIRECT(csv_selection!$B$1 & csv_selection!$C$1 & "!C65") -> pass_thru_industry_adjustments | AZ1: =INDIRECT(csv_selection!$B$1 & csv_selection!$C$1 & "!C66") -> c_corp_asset_adjustments | BA1: =INDIRECT(csv_selection!$B$1 & csv_selection!$C$1 & "!C67") -> pass_thru_asset_adjustments | BB1: =INDIRECT(csv_selection!$B$1 & csv_selection!$C$1 & "!C69") -> c_corp_equity_account_category_share_taxable | BC1: =INDIRECT(csv_selection!$B$1 & csv_selection!$C$1 & "!C70") -> c_corp_equity_account_category_share_deferred | BD1: =INDIRECT(csv_selection!$B$1 & csv_selection!$C$1 & "!C71") -> c_corp_equity_account_category_share_nontaxable | BE1: =INDIRECT(csv_selection!$B$1 & csv_selection!$C$1 & "!C72") -> c_corp_debt_account_category_share_taxable | BF1: =INDIRECT(csv_selection!$B$1 & csv_selection!$C$1 & "!C73") -> c_corp_debt_account_category_share_deferred | BG1: =INDIRECT(csv_selection!$B$1 & csv_selection!$C$1 & "!C74") -> c_corp_debt_account_category_share_nontaxable | BH1: =INDIRECT(csv_selection!$B$1 & csv_selection!$C$1 & "!C75") -> pass_thru_equity_account_category_share_taxable | BI1: =INDIRECT(csv_selection!$B$1 & csv_selection!$C$1 & "!C76") -> pass_thru_equity_account_category_share_deferred | BJ1: =INDIRECT(csv_selection!$B$1 & csv_selection!$C$1 & "!C77") -> pass_thru_equity_account_category_share_nontaxable | BK1: =INDIRECT(csv_selection!$B$1 & csv_selection!$C$1 & "!C78") -> pass_thru_debt_account_category_share_taxable | BL1: =INDIRECT(csv_selection!$B$1 & csv_selection!$C$1 & "!C79") -> pass_thru_debt_account_category_share_deferred | BM1: =INDIRECT(csv_selection!$B$1 & csv_selection!$C$1 & "!C80") -> pass_thru_debt_account_category_share_nontaxable | BN1: =INDIRECT(csv_selection!$B$1 & csv_selection!$C$1 & "!C81") -> ooh_equity_account_category_share_taxable | BO1: =INDIRECT(csv_selection!$B$1 & csv_selection!$C$1 & "!C82") -> ooh_equity_account_category_share_deferred | BP1: =INDIRECT(csv_selection!$B$1 & csv_selection!$C$1 & "!C83") -> ooh_equity_account_category_share_nontaxable | BQ1: =INDIRECT(csv_selection!$B$1 & csv_selection!$C$1 & "!C84") -> ooh_debt_account_category_share_taxable | BR1: =INDIRECT(csv_selection!$B$1 & csv_selection!$C$1 & "!C85") -> ooh_debt_account_category_share_deferred | BS1: =INDIRECT(csv_selection!$B$1 & csv_selection!$C$1 & "!C86") -> ooh_debt_account_category_share_nontaxable
A2: =INDIRECT(csv_selection!$B$1 & csv_selection!$C$1 & "!D2") -> 2026 | B2: =INDIRECT(csv_selection!$B$1 & csv_selection!$C$1 & "!D5") -> 0.21 | C2: =INDIRECT(csv_selection!$B$1 & csv_selection!$C$1 & "!D6") -> 0.3042 | D2: =INDIRECT(csv_selection!$B$1 & csv_selection!$C$1 & "!D7") -> 0.0352 | E2: =INDIRECT(csv_selection!$B$1 & csv_selection!$C$1 & "!D8") -> 0.01 | F2: =INDIRECT(csv_selection!$B$1 & csv_selection!$C$1 & "!D9") -> 0 | G2: =INDIRECT(csv_selection!$B$1 & csv_selection!$C$1 & "!D11") -> 0.1997 | H2: =INDIRECT(csv_selection!$B$1 & csv_selection!$C$1 & "!D12") -> 0.3495 | I2: =INDIRECT(csv_selection!$B$1 & csv_selection!$C$1 & "!D13") -> 0.2116 | J2: =INDIRECT(csv_selection!$B$1 & csv_selection!$C$1 & "!D14") -> 0 | K2: =INDIRECT(csv_selection!$B$1 & csv_selection!$C$1 & "!D15") -> 0.3036 | L2: =INDIRECT(csv_selection!$B$1 & csv_selection!$C$1 & "!D16") -> 0.3036 | M2: =INDIRECT(csv_selection!$B$1 & csv_selection!$C$1 & "!D17") -> 0.231 | N2: =INDIRECT(csv_selection!$B$1 & csv_selection!$C$1 & "!D18") -> 0 | O2: =INDIRECT(csv_selection!$B$1 & csv_selection!$C$1 & "!D20") -> 0.1949 | P2: =INDIRECT(csv_selection!$B$1 & csv_selection!$C$1 & "!D21") -> 0.1776 | Q2: =INDIRECT(csv_selection!$B$1 & csv_selection!$C$1 & "!D23") -> 0.3225 | R2: =INDIRECT(csv_selection!$B$1 & csv_selection!$C$1 & "!D24") -> 0.7734 | S2: =INDIRECT(csv_selection!$B$1 & csv_selection!$C$1 & "!D25") -> 0.9884 | T2: =INDIRECT(csv_selection!$B$1 & csv_selection!$C$1 & "!D26") -> 0.9933 | U2: =INDIRECT(csv_selection!$B$1 & csv_selection!$C$1 & "!D27") -> 0.5552 | V2: =INDIRECT(csv_selection!$B$1 & csv_selection!$C$1 & "!D28") -> 0.3457 | W2: =INDIRECT(csv_selection!$B$1 & csv_selection!$C$1 & "!D31") -> 1 | X2: =INDIRECT(csv_selection!$B$1 & csv_selection!$C$1 & "!D32") -> 1 | Y2: =INDIRECT(csv_selection!$B$1 & csv_selection!$C$1 & "!D33") -> 1 | Z2: =INDIRECT(csv_selection!$B$1 & csv_selection!$C$1 & "!D34") -> 1 | AA2: =INDIRECT(csv_selection!$B$1 & csv_selection!$C$1 & "!D35") -> 1 | AB2: =INDIRECT(csv_selection!$B$1 & csv_selection!$C$1 & "!D36") -> 1 | AC2: =INDIRECT(csv_selection!$B$1 & csv_selection!$C$1 & "!D37") -> 1 | AD2: =INDIRECT(csv_selection!$B$1 & csv_selection!$C$1 & "!D38") -> 1 | AE2: =INDIRECT(csv_selection!$B$1 & csv_selection!$C$1 & "!D40") -> 0 | AF2: =INDIRECT(csv_selection!$B$1 & csv_selection!$C$1 & "!D41") -> 0 | AG2: =INDIRECT(csv_selection!$B$1 & csv_selection!$C$1 & "!D42") -> 0 | AH2: =INDIRECT(csv_selection!$B$1 & csv_selection!$C$1 & "!D43") -> 0 | AI2: =INDIRECT(csv_selection!$B$1 & csv_selection!$C$1 & "!D44") -> 0 | AJ2: =INDIRECT(csv_selection!$B$1 & csv_selection!$C$1 & "!D45") -> 0 | AK2: =INDIRECT(csv_selection!$B$1 & csv_selection!$C$1 & "!D46") -> 0 | AL2: =INDIRECT(csv_selection!$B$1 & csv_selection!$C$1 & "!D47") -> 0 | AM2: =INDIRECT(csv_selection!$B$1 & csv_selection!$C$1 & "!D50") -> CLaw_perm | AN2: =INDIRECT(csv_selection!$B$1 & csv_selection!$C$1 & "!D51") -> CLaw_perm | AO2: =INDIRECT(csv_selection!$B$1 & csv_selection!$C$1 & "!D52") -> CLaw_perm | AP2: =INDIRECT(csv_selection!$B$1 & csv_selection!$C$1 & "!D53") -> CLaw_perm | AQ2: =INDIRECT(csv_selection!$B$1 & csv_selection!$C$1 & "!D54") -> CLCC_perm | AR2: =INDIRECT(csv_selection!$B$1 & csv_selection!$C$1 & "!D55") -> CLPT_perm | AS2: =INDIRECT(csv_selection!$B$1 & csv_selection!$C$1 & "!D56") -> CLaw_temp | AT2: =INDIRECT(csv_selection!$B$1 & csv_selection!$C$1 & "!D58") -> CLaw_2026 | AU2: =INDIRECT(csv_selection!$B$1 & csv_selection!$C$1 & "!D59") -> CLaw_rduc | AV2: =INDIRECT(csv_selection!$B$1 & csv_selection!$C$1 & "!D61") -> CLaw_2026 | AW2: =INDIRECT(csv_selection!$B$1 & csv_selection!$C$1 & "!D63") -> CLaw_perm | AX2: =INDIRECT(csv_selection!$B$1 & csv_selection!$C$1 & "!D64") -> CLaw_perm | AY2: =INDIRECT(csv_selection!$B$1 & csv_selection!$C$1 & "!D65") -> CLaw_perm | AZ2: =INDIRECT(csv_selection!$B$1 & csv_selection!$C$1 & "!D66") -> CLaw_perm | BA2: =INDIRECT(csv_selection!$B$1 & csv_selection!$C$1 & "!D67") -> CLaw_perm | BB2: =INDIRECT(csv_selection!$B$1 & csv_selection!$C$1 & "!D69") -> 0.6241 | BC2: =INDIRECT(csv_selection!$B$1 & csv_selection!$C$1 & "!D70") -> 0.0335 | BD2: =INDIRECT(csv_selection!$B$1 & csv_selection!$C$1 & "!D71") -> 0.3424 | BE2: =INDIRECT(csv_selection!$B$1 & csv_selection!$C$1 & "!D72") -> 0.387 | BF2: =INDIRECT(csv_selection!$B$1 & csv_selection!$C$1 & "!D73") -> 0.1925 | BG2: =INDIRECT(csv_selection!$B$1 & csv_selection!$C$1 & "!D74") -> 0.4205 | BH2: =INDIRECT(csv_selection!$B$1 & csv_selection!$C$1 & "!D75") -> 1 | BI2: =INDIRECT(csv_selection!$B$1 & csv_selection!$C$1 & "!D76") -> 0 | BJ2: =INDIRECT(csv_selection!$B$1 & csv_selection!$C$1 & "!D77") -> 0 | BK2: =INDIRECT(csv_selection!$B$1 & csv_selection!$C$1 & "!D78") -> 0.6887 | BL2: =INDIRECT(csv_selection!$B$1 & csv_selection!$C$1 & "!D79") -> 0.1284 | BM2: =INDIRECT(csv_selection!$B$1 & csv_selection!$C$1 & "!D80") -> 0.1829 | BN2: =INDIRECT(csv_selection!$B$1 & csv_selection!$C$1 & "!D81") -> 1 | BO2: =INDIRECT(csv_selection!$B$1 & csv_selection!$C$1 & "!D82") -> 0 | BP2: =INDIRECT(csv_selection!$B$1 & csv_selection!$C$1 & "!D83") -> 0 | BQ2: =INDIRECT(csv_selection!$B$1 & csv_selection!$C$1 & "!D84") -> 0.8127 | BR2: =INDIRECT(csv_selection!$B$1 & csv_selection!$C$1 & "!D85") -> 0.0578 | BS2: =INDIRECT(csv_selection!$B$1 & csv_selection!$C$1 & "!D86") -> 0.1295
A3: =INDIRECT(csv_selection!$B$1 & csv_selection!$C$1 & "!E2") -> 2027 | B3: =INDIRECT(csv_selection!$B$1 & csv_selection!$C$1 & "!E5") -> 0.21 | C3: =INDIRECT(csv_selection!$B$1 & csv_selection!$C$1 & "!E6") -> 0.3056 | D3: =INDIRECT(csv_selection!$B$1 & csv_selection!$C$1 & "!E7") -> 0.0352 | E3: =INDIRECT(csv_selection!$B$1 & csv_selection!$C$1 & "!E8") -> 0.01 | F3: =INDIRECT(csv_selection!$B$1 & csv_selection!$C$1 & "!E9") -> 0 | G3: =INDIRECT(csv_selection!$B$1 & csv_selection!$C$1 & "!E11") -> 0.1999 | H3: =INDIRECT(csv_selection!$B$1 & csv_selection!$C$1 & "!E12") -> 0.3445 | I3: =INDIRECT(csv_selection!$B$1 & csv_selection!$C$1 & "!E13") -> 0.2095 | J3: =INDIRECT(csv_selection!$B$1 & csv_selection!$C$1 & "!E14") -> 0 | K3: =INDIRECT(csv_selection!$B$1 & csv_selection!$C$1 & "!E15") -> 0.3044 | L3: =INDIRECT(csv_selection!$B$1 & csv_selection!$C$1 & "!E16") -> 0.3044 | M3: =INDIRECT(csv_selection!$B$1 & csv_selection!$C$1 & "!E17") -> 0.2308 | N3: =INDIRECT(csv_selection!$B$1 & csv_selection!$C$1 & "!E18") -> 0 | O3: =INDIRECT(csv_selection!$B$1 & csv_selection!$C$1 & "!E20") -> 0.1947 | P3: =INDIRECT(csv_selection!$B$1 & csv_selection!$C$1 & "!E21") -> 0.1778 | Q3: =INDIRECT(csv_selection!$B$1 & csv_selection!$C$1 & "!E23") -> 0.318 | R3: =INDIRECT(csv_selection!$B$1 & csv_selection!$C$1 & "!E24") -> 0.7741 | S3: =INDIRECT(csv_selection!$B$1 & csv_selection!$C$1 & "!E25") -> 0.9815 | T3: =INDIRECT(csv_selection!$B$1 & csv_selection!$C$1 & "!E26") -> 0.9894 | U3: =INDIRECT(csv_selection!$B$1 & csv_selection!$C$1 & "!E27") -> 0.5876 | V3: =INDIRECT(csv_selection!$B$1 & csv_selection!$C$1 & "!E28") -> 0.356 | W3: =INDIRECT(csv_selection!$B$1 & csv_selection!$C$1 & "!E31") -> 1 | X3: =INDIRECT(csv_selection!$B$1 & csv_selection!$C$1 & "!E32") -> 1 | Y3: =INDIRECT(csv_selection!$B$1 & csv_selection!$C$1 & "!E33") -> 1 | Z3: =INDIRECT(csv_selection!$B$1 & csv_selection!$C$1 & "!E34") -> 1 | AA3: =INDIRECT(csv_selection!$B$1 & csv_selection!$C$1 & "!E35") -> 1 | AB3: =INDIRECT(csv_selection!$B$1 & csv_selection!$C$1 & "!E36") -> 1 | AC3: =INDIRECT(csv_selection!$B$1 & csv_selection!$C$1 & "!E37") -> 1 | AD3: =INDIRECT(csv_selection!$B$1 & csv_selection!$C$1 & "!E38") -> 1 | AE3: =INDIRECT(csv_selection!$B$1 & csv_selection!$C$1 & "!E40") -> 0 | AF3: =INDIRECT(csv_selection!$B$1 & csv_selection!$C$1 & "!E41") -> 0 | AG3: =INDIRECT(csv_selection!$B$1 & csv_selection!$C$1 & "!E42") -> 0 | AH3: =INDIRECT(csv_selection!$B$1 & csv_selection!$C$1 & "!E43") -> 0 | AI3: =INDIRECT(csv_selection!$B$1 & csv_selection!$C$1 & "!E44") -> 0 | AJ3: =INDIRECT(csv_selection!$B$1 & csv_selection!$C$1 & "!E45") -> 0 | AK3: =INDIRECT(csv_selection!$B$1 & csv_selection!$C$1 & "!E46") -> 0 | AL3: =INDIRECT(csv_selection!$B$1 & csv_selection!$C$1 & "!E47") -> 0 | AM3: =INDIRECT(csv_selection!$B$1 & csv_selection!$C$1 & "!E50") -> CLaw_perm | AN3: =INDIRECT(csv_selection!$B$1 & csv_selection!$C$1 & "!E51") -> CLaw_perm | AO3: =INDIRECT(csv_selection!$B$1 & csv_selection!$C$1 & "!E52") -> CLaw_perm | AP3: =INDIRECT(csv_selection!$B$1 & csv_selection!$C$1 & "!E53") -> CLaw_perm | AQ3: =INDIRECT(csv_selection!$B$1 & csv_selection!$C$1 & "!E54") -> CLCC_perm | AR3: =INDIRECT(csv_selection!$B$1 & csv_selection!$C$1 & "!E55") -> CLPT_perm | AS3: =INDIRECT(csv_selection!$B$1 & csv_selection!$C$1 & "!E56") -> CLaw_temp | AT3: =INDIRECT(csv_selection!$B$1 & csv_selection!$C$1 & "!E58") -> Claw_perm | AU3: =INDIRECT(csv_selection!$B$1 & csv_selection!$C$1 & "!E59") -> CLaw_rduc | AV3: =INDIRECT(csv_selection!$B$1 & csv_selection!$C$1 & "!E61") -> CLaw_2027 | AW3: =INDIRECT(csv_selection!$B$1 & csv_selection!$C$1 & "!E63") -> CLaw_perm | AX3: =INDIRECT(csv_selection!$B$1 & csv_selection!$C$1 & "!E64") -> CLaw_perm | AY3: =INDIRECT(csv_selection!$B$1 & csv_selection!$C$1 & "!E65") -> CLaw_perm | AZ3: =INDIRECT(csv_selection!$B$1 & csv_selection!$C$1 & "!E66") -> CLaw_perm | BA3: =INDIRECT(csv_selection!$B$1 & csv_selection!$C$1 & "!E67") -> CLaw_perm | BB3: =INDIRECT(csv_selection!$B$1 & csv_selection!$C$1 & "!E69") -> 0.63 | BC3: =INDIRECT(csv_selection!$B$1 & csv_selection!$C$1 & "!E70") -> 0.0335 | BD3: =INDIRECT(csv_selection!$B$1 & csv_selection!$C$1 & "!E71") -> 0.3365 | BE3: =INDIRECT(csv_selection!$B$1 & csv_selection!$C$1 & "!E72") -> 0.3917 | BF3: =INDIRECT(csv_selection!$B$1 & csv_selection!$C$1 & "!E73") -> 0.1925 | BG3: =INDIRECT(csv_selection!$B$1 & csv_selection!$C$1 & "!E74") -> 0.4158 | BH3: =INDIRECT(csv_selection!$B$1 & csv_selection!$C$1 & "!E75") -> 1 | BI3: =INDIRECT(csv_selection!$B$1 & csv_selection!$C$1 & "!E76") -> 0 | BJ3: =INDIRECT(csv_selection!$B$1 & csv_selection!$C$1 & "!E77") -> 0 | BK3: =INDIRECT(csv_selection!$B$1 & csv_selection!$C$1 & "!E78") -> 0.6907 | BL3: =INDIRECT(csv_selection!$B$1 & csv_selection!$C$1 & "!E79") -> 0.1284 | BM3: =INDIRECT(csv_selection!$B$1 & csv_selection!$C$1 & "!E80") -> 0.1809 | BN3: =INDIRECT(csv_selection!$B$1 & csv_selection!$C$1 & "!E81") -> 1 | BO3: =INDIRECT(csv_selection!$B$1 & csv_selection!$C$1 & "!E82") -> 0 | BP3: =INDIRECT(csv_selection!$B$1 & csv_selection!$C$1 & "!E83") -> 0 | BQ3: =INDIRECT(csv_selection!$B$1 & csv_selection!$C$1 & "!E84") -> 0.8138 | BR3: =INDIRECT(csv_selection!$B$1 & csv_selection!$C$1 & "!E85") -> 0.0578 | BS3: =INDIRECT(csv_selection!$B$1 & csv_selection!$C$1 & "!E86") -> 0.1284
A4: =INDIRECT(csv_selection!$B$1 & csv_selection!$C$1 & "!F2") -> 2028 | B4: =INDIRECT(csv_selection!$B$1 & csv_selection!$C$1 & "!F5") -> 0.21 | C4: =INDIRECT(csv_selection!$B$1 & csv_selection!$C$1 & "!F6") -> 0.3051 | D4: =INDIRECT(csv_selection!$B$1 & csv_selection!$C$1 & "!F7") -> 0.0352 | E4: =INDIRECT(csv_selection!$B$1 & csv_selection!$C$1 & "!F8") -> 0.01 | F4: =INDIRECT(csv_selection!$B$1 & csv_selection!$C$1 & "!F9") -> 0 | G4: =INDIRECT(csv_selection!$B$1 & csv_selection!$C$1 & "!F11") -> 0.2006 | H4: =INDIRECT(csv_selection!$B$1 & csv_selection!$C$1 & "!F12") -> 0.3409 | I4: =INDIRECT(csv_selection!$B$1 & csv_selection!$C$1 & "!F13") -> 0.2072 | J4: =INDIRECT(csv_selection!$B$1 & csv_selection!$C$1 & "!F14") -> 0 | K4: =INDIRECT(csv_selection!$B$1 & csv_selection!$C$1 & "!F15") -> 0.3045 | L4: =INDIRECT(csv_selection!$B$1 & csv_selection!$C$1 & "!F16") -> 0.3045 | M4: =INDIRECT(csv_selection!$B$1 & csv_selection!$C$1 & "!F17") -> 0.2339 | N4: =INDIRECT(csv_selection!$B$1 & csv_selection!$C$1 & "!F18") -> 0 | O4: =INDIRECT(csv_selection!$B$1 & csv_selection!$C$1 & "!F20") -> 0.1943 | P4: =INDIRECT(csv_selection!$B$1 & csv_selection!$C$1 & "!F21") -> 0.1774 | Q4: =INDIRECT(csv_selection!$B$1 & csv_selection!$C$1 & "!F23") -> 0.3209 | R4: =INDIRECT(csv_selection!$B$1 & csv_selection!$C$1 & "!F24") -> 0.7749 | S4: =INDIRECT(csv_selection!$B$1 & csv_selection!$C$1 & "!F25") -> 0.9768 | T4: =INDIRECT(csv_selection!$B$1 & csv_selection!$C$1 & "!F26") -> 0.9867 | U4: =INDIRECT(csv_selection!$B$1 & csv_selection!$C$1 & "!F27") -> 0.6222 | V4: =INDIRECT(csv_selection!$B$1 & csv_selection!$C$1 & "!F28") -> 0.3709 | W4: =INDIRECT(csv_selection!$B$1 & csv_selection!$C$1 & "!F31") -> 1 | X4: =INDIRECT(csv_selection!$B$1 & csv_selection!$C$1 & "!F32") -> 1 | Y4: =INDIRECT(csv_selection!$B$1 & csv_selection!$C$1 & "!F33") -> 1 | Z4: =INDIRECT(csv_selection!$B$1 & csv_selection!$C$1 & "!F34") -> 1 | AA4: =INDIRECT(csv_selection!$B$1 & csv_selection!$C$1 & "!F35") -> 1 | AB4: =INDIRECT(csv_selection!$B$1 & csv_selection!$C$1 & "!F36") -> 1 | AC4: =INDIRECT(csv_selection!$B$1 & csv_selection!$C$1 & "!F37") -> 1 | AD4: =INDIRECT(csv_selection!$B$1 & csv_selection!$C$1 & "!F38") -> 1 | AE4: =INDIRECT(csv_selection!$B$1 & csv_selection!$C$1 & "!F40") -> 0 | AF4: =INDIRECT(csv_selection!$B$1 & csv_selection!$C$1 & "!F41") -> 0 | AG4: =INDIRECT(csv_selection!$B$1 & csv_selection!$C$1 & "!F42") -> 0 | AH4: =INDIRECT(csv_selection!$B$1 & csv_selection!$C$1 & "!F43") -> 0 | AI4: =INDIRECT(csv_selection!$B$1 & csv_selection!$C$1 & "!F44") -> 0 | AJ4: =INDIRECT(csv_selection!$B$1 & csv_selection!$C$1 & "!F45") -> 0 | AK4: =INDIRECT(csv_selection!$B$1 & csv_selection!$C$1 & "!F46") -> 0 | AL4: =INDIRECT(csv_selection!$B$1 & csv_selection!$C$1 & "!F47") -> 0 | AM4: =INDIRECT(csv_selection!$B$1 & csv_selection!$C$1 & "!F50") -> CLaw_perm | AN4: =INDIRECT(csv_selection!$B$1 & csv_selection!$C$1 & "!F51") -> CLaw_perm | AO4: =INDIRECT(csv_selection!$B$1 & csv_selection!$C$1 & "!F52") -> CLaw_perm | AP4: =INDIRECT(csv_selection!$B$1 & csv_selection!$C$1 & "!F53") -> CLaw_perm | AQ4: =INDIRECT(csv_selection!$B$1 & csv_selection!$C$1 & "!F54") -> CLCC_perm | AR4: =INDIRECT(csv_selection!$B$1 & csv_selection!$C$1 & "!F55") -> CLPT_perm | AS4: =INDIRECT(csv_selection!$B$1 & csv_selection!$C$1 & "!F56") -> CLaw_temp | AT4: =INDIRECT(csv_selection!$B$1 & csv_selection!$C$1 & "!F58") -> Claw_perm | AU4: =INDIRECT(csv_selection!$B$1 & csv_selection!$C$1 & "!F59") -> CLaw_rduc | AV4: =INDIRECT(csv_selection!$B$1 & csv_selection!$C$1 & "!F61") -> CLaw_2028 | AW4: =INDIRECT(csv_selection!$B$1 & csv_selection!$C$1 & "!F63") -> CLaw_perm | AX4: =INDIRECT(csv_selection!$B$1 & csv_selection!$C$1 & "!F64") -> CLaw_perm | AY4: =INDIRECT(csv_selection!$B$1 & csv_selection!$C$1 & "!F65") -> CLaw_perm | AZ4: =INDIRECT(csv_selection!$B$1 & csv_selection!$C$1 & "!F66") -> CLaw_perm | BA4: =INDIRECT(csv_selection!$B$1 & csv_selection!$C$1 & "!F67") -> CLaw_perm | BB4: =INDIRECT(csv_selection!$B$1 & csv_selection!$C$1 & "!F69") -> 0.627 | BC4: =INDIRECT(csv_selection!$B$1 & csv_selection!$C$1 & "!F70") -> 0.0335 | BD4: =INDIRECT(csv_selection!$B$1 & csv_selection!$C$1 & "!F71") -> 0.3395 | BE4: =INDIRECT(csv_selection!$B$1 & csv_selection!$C$1 & "!F72") -> 0.3889 | BF4: =INDIRECT(csv_selection!$B$1 & csv_selection!$C$1 & "!F73") -> 0.1925 | BG4: =INDIRECT(csv_selection!$B$1 & csv_selection!$C$1 & "!F74") -> 0.4186 | BH4: =INDIRECT(csv_selection!$B$1 & csv_selection!$C$1 & "!F75") -> 1 | BI4: =INDIRECT(csv_selection!$B$1 & csv_selection!$C$1 & "!F76") -> 0 | BJ4: =INDIRECT(csv_selection!$B$1 & csv_selection!$C$1 & "!F77") -> 0 | BK4: =INDIRECT(csv_selection!$B$1 & csv_selection!$C$1 & "!F78") -> 0.6896 | BL4: =INDIRECT(csv_selection!$B$1 & csv_selection!$C$1 & "!F79") -> 0.1284 | BM4: =INDIRECT(csv_selection!$B$1 & csv_selection!$C$1 & "!F80") -> 0.182 | BN4: =INDIRECT(csv_selection!$B$1 & csv_selection!$C$1 & "!F81") -> 1 | BO4: =INDIRECT(csv_selection!$B$1 & csv_selection!$C$1 & "!F82") -> 0 | BP4: =INDIRECT(csv_selection!$B$1 & csv_selection!$C$1 & "!F83") -> 0 | BQ4: =INDIRECT(csv_selection!$B$1 & csv_selection!$C$1 & "!F84") -> 0.8133 | BR4: =INDIRECT(csv_selection!$B$1 & csv_selection!$C$1 & "!F85") -> 0.0578 | BS4: =INDIRECT(csv_selection!$B$1 & csv_selection!$C$1 & "!F86") -> 0.1289
A5: =INDIRECT(csv_selection!$B$1 & csv_selection!$C$1 & "!G2") -> 2029 | B5: =INDIRECT(csv_selection!$B$1 & csv_selection!$C$1 & "!G5") -> 0.21 | C5: =INDIRECT(csv_selection!$B$1 & csv_selection!$C$1 & "!G6") -> 0.3103 | D5: =INDIRECT(csv_selection!$B$1 & csv_selection!$C$1 & "!G7") -> 0.0352 | E5: =INDIRECT(csv_selection!$B$1 & csv_selection!$C$1 & "!G8") -> 0.01 | F5: =INDIRECT(csv_selection!$B$1 & csv_selection!$C$1 & "!G9") -> 0 | G5: =INDIRECT(csv_selection!$B$1 & csv_selection!$C$1 & "!G11") -> 0.1968 | H5: =INDIRECT(csv_selection!$B$1 & csv_selection!$C$1 & "!G12") -> 0.3347 | I5: =INDIRECT(csv_selection!$B$1 & csv_selection!$C$1 & "!G13") -> 0.2051 | J5: =INDIRECT(csv_selection!$B$1 & csv_selection!$C$1 & "!G14") -> 0 | K5: =INDIRECT(csv_selection!$B$1 & csv_selection!$C$1 & "!G15") -> 0.3041 | L5: =INDIRECT(csv_selection!$B$1 & csv_selection!$C$1 & "!G16") -> 0.3041 | M5: =INDIRECT(csv_selection!$B$1 & csv_selection!$C$1 & "!G17") -> 0.2311 | N5: =INDIRECT(csv_selection!$B$1 & csv_selection!$C$1 & "!G18") -> 0 | O5: =INDIRECT(csv_selection!$B$1 & csv_selection!$C$1 & "!G20") -> 0.1976 | P5: =INDIRECT(csv_selection!$B$1 & csv_selection!$C$1 & "!G21") -> 0.1817 | Q5: =INDIRECT(csv_selection!$B$1 & csv_selection!$C$1 & "!G23") -> 0.3133 | R5: =INDIRECT(csv_selection!$B$1 & csv_selection!$C$1 & "!G24") -> 0.775 | S5: =INDIRECT(csv_selection!$B$1 & csv_selection!$C$1 & "!G25") -> 0.9739 | T5: =INDIRECT(csv_selection!$B$1 & csv_selection!$C$1 & "!G26") -> 0.985 | U5: =INDIRECT(csv_selection!$B$1 & csv_selection!$C$1 & "!G27") -> 0.6473 | V5: =INDIRECT(csv_selection!$B$1 & csv_selection!$C$1 & "!G28") -> 0.3781 | W5: =INDIRECT(csv_selection!$B$1 & csv_selection!$C$1 & "!G31") -> 1 | X5: =INDIRECT(csv_selection!$B$1 & csv_selection!$C$1 & "!G32") -> 1 | Y5: =INDIRECT(csv_selection!$B$1 & csv_selection!$C$1 & "!G33") -> 1 | Z5: =INDIRECT(csv_selection!$B$1 & csv_selection!$C$1 & "!G34") -> 1 | AA5: =INDIRECT(csv_selection!$B$1 & csv_selection!$C$1 & "!G35") -> 1 | AB5: =INDIRECT(csv_selection!$B$1 & csv_selection!$C$1 & "!G36") -> 1 | AC5: =INDIRECT(csv_selection!$B$1 & csv_selection!$C$1 & "!G37") -> 1 | AD5: =INDIRECT(csv_selection!$B$1 & csv_selection!$C$1 & "!G38") -> 1 | AE5: =INDIRECT(csv_selection!$B$1 & csv_selection!$C$1 & "!G40") -> 0 | AF5: =INDIRECT(csv_selection!$B$1 & csv_selection!$C$1 & "!G41") -> 0 | AG5: =INDIRECT(csv_selection!$B$1 & csv_selection!$C$1 & "!G42") -> 0 | AH5: =INDIRECT(csv_selection!$B$1 & csv_selection!$C$1 & "!G43") -> 0 | AI5: =INDIRECT(csv_selection!$B$1 & csv_selection!$C$1 & "!G44") -> 0 | AJ5: =INDIRECT(csv_selection!$B$1 & csv_selection!$C$1 & "!G45") -> 0 | AK5: =INDIRECT(csv_selection!$B$1 & csv_selection!$C$1 & "!G46") -> 0 | AL5: =INDIRECT(csv_selection!$B$1 & csv_selection!$C$1 & "!G47") -> 0 | AM5: =INDIRECT(csv_selection!$B$1 & csv_selection!$C$1 & "!G50") -> CLaw_perm | AN5: =INDIRECT(csv_selection!$B$1 & csv_selection!$C$1 & "!G51") -> CLaw_perm | AO5: =INDIRECT(csv_selection!$B$1 & csv_selection!$C$1 & "!G52") -> CLaw_perm | AP5: =INDIRECT(csv_selection!$B$1 & csv_selection!$C$1 & "!G53") -> CLaw_perm | AQ5: =INDIRECT(csv_selection!$B$1 & csv_selection!$C$1 & "!G54") -> CLCC_perm | AR5: =INDIRECT(csv_selection!$B$1 & csv_selection!$C$1 & "!G55") -> CLPT_perm | AS5: =INDIRECT(csv_selection!$B$1 & csv_selection!$C$1 & "!G56") -> CLaw_perm | AT5: =INDIRECT(csv_selection!$B$1 & csv_selection!$C$1 & "!G58") -> Claw_perm | AU5: =INDIRECT(csv_selection!$B$1 & csv_selection!$C$1 & "!G59") -> CLaw_rduc | AV5: =INDIRECT(csv_selection!$B$1 & csv_selection!$C$1 & "!G61") -> CLaw_2029 | AW5: =INDIRECT(csv_selection!$B$1 & csv_selection!$C$1 & "!G63") -> CLaw_perm | AX5: =INDIRECT(csv_selection!$B$1 & csv_selection!$C$1 & "!G64") -> CLaw_perm | AY5: =INDIRECT(csv_selection!$B$1 & csv_selection!$C$1 & "!G65") -> CLaw_perm | AZ5: =INDIRECT(csv_selection!$B$1 & csv_selection!$C$1 & "!G66") -> CLaw_perm | BA5: =INDIRECT(csv_selection!$B$1 & csv_selection!$C$1 & "!G67") -> CLaw_perm | BB5: =INDIRECT(csv_selection!$B$1 & csv_selection!$C$1 & "!G69") -> 0.6321 | BC5: =INDIRECT(csv_selection!$B$1 & csv_selection!$C$1 & "!G70") -> 0.0335 | BD5: =INDIRECT(csv_selection!$B$1 & csv_selection!$C$1 & "!G71") -> 0.3344 | BE5: =INDIRECT(csv_selection!$B$1 & csv_selection!$C$1 & "!G72") -> 0.3934 | BF5: =INDIRECT(csv_selection!$B$1 & csv_selection!$C$1 & "!G73") -> 0.1925 | BG5: =INDIRECT(csv_selection!$B$1 & csv_selection!$C$1 & "!G74") -> 0.4141 | BH5: =INDIRECT(csv_selection!$B$1 & csv_selection!$C$1 & "!G75") -> 1 | BI5: =INDIRECT(csv_selection!$B$1 & csv_selection!$C$1 & "!G76") -> 0 | BJ5: =INDIRECT(csv_selection!$B$1 & csv_selection!$C$1 & "!G77") -> 0 | BK5: =INDIRECT(csv_selection!$B$1 & csv_selection!$C$1 & "!G78") -> 0.6915 | BL5: =INDIRECT(csv_selection!$B$1 & csv_selection!$C$1 & "!G79") -> 0.1284 | BM5: =INDIRECT(csv_selection!$B$1 & csv_selection!$C$1 & "!G80") -> 0.1801 | BN5: =INDIRECT(csv_selection!$B$1 & csv_selection!$C$1 & "!G81") -> 1 | BO5: =INDIRECT(csv_selection!$B$1 & csv_selection!$C$1 & "!G82") -> 0 | BP5: =INDIRECT(csv_selection!$B$1 & csv_selection!$C$1 & "!G83") -> 0 | BQ5: =INDIRECT(csv_selection!$B$1 & csv_selection!$C$1 & "!G84") -> 0.8143 | BR5: =INDIRECT(csv_selection!$B$1 & csv_selection!$C$1 & "!G85") -> 0.0578 | BS5: =INDIRECT(csv_selection!$B$1 & csv_selection!$C$1 & "!G86") -> 0.1279
A6: =INDIRECT(csv_selection!$B$1 & csv_selection!$C$1 & "!H2") -> 2030 | B6: =INDIRECT(csv_selection!$B$1 & csv_selection!$C$1 & "!H5") -> 0.21 | C6: =INDIRECT(csv_selection!$B$1 & csv_selection!$C$1 & "!H6") -> 0.3121 | D6: =INDIRECT(csv_selection!$B$1 & csv_selection!$C$1 & "!H7") -> 0.0352 | E6: =INDIRECT(csv_selection!$B$1 & csv_selection!$C$1 & "!H8") -> 0.01 | F6: =INDIRECT(csv_selection!$B$1 & csv_selection!$C$1 & "!H9") -> 0 | G6: =INDIRECT(csv_selection!$B$1 & csv_selection!$C$1 & "!H11") -> 0.1991 | H6: =INDIRECT(csv_selection!$B$1 & csv_selection!$C$1 & "!H12") -> 0.3331 | I6: =INDIRECT(csv_selection!$B$1 & csv_selection!$C$1 & "!H13") -> 0.2041 | J6: =INDIRECT(csv_selection!$B$1 & csv_selection!$C$1 & "!H14") -> 0 | K6: =INDIRECT(csv_selection!$B$1 & csv_selection!$C$1 & "!H15") -> 0.3064 | L6: =INDIRECT(csv_selection!$B$1 & csv_selection!$C$1 & "!H16") -> 0.3064 | M6: =INDIRECT(csv_selection!$B$1 & csv_selection!$C$1 & "!H17") -> 0.2331 | N6: =INDIRECT(csv_selection!$B$1 & csv_selection!$C$1 & "!H18") -> 0 | O6: =INDIRECT(csv_selection!$B$1 & csv_selection!$C$1 & "!H20") -> 0.1978 | P6: =INDIRECT(csv_selection!$B$1 & csv_selection!$C$1 & "!H21") -> 0.1816 | Q6: =INDIRECT(csv_selection!$B$1 & csv_selection!$C$1 & "!H23") -> 0.305 | R6: =INDIRECT(csv_selection!$B$1 & csv_selection!$C$1 & "!H24") -> 0.7743 | S6: =INDIRECT(csv_selection!$B$1 & csv_selection!$C$1 & "!H25") -> 0.9724 | T6: =INDIRECT(csv_selection!$B$1 & csv_selection!$C$1 & "!H26") -> 0.9841 | U6: =INDIRECT(csv_selection!$B$1 & csv_selection!$C$1 & "!H27") -> 0.5526 | V6: =INDIRECT(csv_selection!$B$1 & csv_selection!$C$1 & "!H28") -> 0.0435 | W6: =INDIRECT(csv_selection!$B$1 & csv_selection!$C$1 & "!H31") -> 1 | X6: =INDIRECT(csv_selection!$B$1 & csv_selection!$C$1 & "!H32") -> 1 | Y6: =INDIRECT(csv_selection!$B$1 & csv_selection!$C$1 & "!H33") -> 1 | Z6: =INDIRECT(csv_selection!$B$1 & csv_selection!$C$1 & "!H34") -> 1 | AA6: =INDIRECT(csv_selection!$B$1 & csv_selection!$C$1 & "!H35") -> 1 | AB6: =INDIRECT(csv_selection!$B$1 & csv_selection!$C$1 & "!H36") -> 1 | AC6: =INDIRECT(csv_selection!$B$1 & csv_selection!$C$1 & "!H37") -> 1 | AD6: =INDIRECT(csv_selection!$B$1 & csv_selection!$C$1 & "!H38") -> 1 | AE6: =INDIRECT(csv_selection!$B$1 & csv_selection!$C$1 & "!H40") -> 0 | AF6: =INDIRECT(csv_selection!$B$1 & csv_selection!$C$1 & "!H41") -> 0 | AG6: =INDIRECT(csv_selection!$B$1 & csv_selection!$C$1 & "!H42") -> 0 | AH6: =INDIRECT(csv_selection!$B$1 & csv_selection!$C$1 & "!H43") -> 0 | AI6: =INDIRECT(csv_selection!$B$1 & csv_selection!$C$1 & "!H44") -> 0 | AJ6: =INDIRECT(csv_selection!$B$1 & csv_selection!$C$1 & "!H45") -> 0 | AK6: =INDIRECT(csv_selection!$B$1 & csv_selection!$C$1 & "!H46") -> 0 | AL6: =INDIRECT(csv_selection!$B$1 & csv_selection!$C$1 & "!H47") -> 0 | AM6: =INDIRECT(csv_selection!$B$1 & csv_selection!$C$1 & "!H50") -> CLaw_perm | AN6: =INDIRECT(csv_selection!$B$1 & csv_selection!$C$1 & "!H51") -> CLaw_perm | AO6: =INDIRECT(csv_selection!$B$1 & csv_selection!$C$1 & "!H52") -> CLaw_perm | AP6: =INDIRECT(csv_selection!$B$1 & csv_selection!$C$1 & "!H53") -> CLaw_perm | AQ6: =INDIRECT(csv_selection!$B$1 & csv_selection!$C$1 & "!H54") -> CLCC_perm | AR6: =INDIRECT(csv_selection!$B$1 & csv_selection!$C$1 & "!H55") -> CLPT_perm | AS6: =INDIRECT(csv_selection!$B$1 & csv_selection!$C$1 & "!H56") -> CLaw_perm | AT6: =INDIRECT(csv_selection!$B$1 & csv_selection!$C$1 & "!H58") -> Claw_perm | AU6: =INDIRECT(csv_selection!$B$1 & csv_selection!$C$1 & "!H59") -> CLaw_rduc | AV6: =INDIRECT(csv_selection!$B$1 & csv_selection!$C$1 & "!H61") -> CLaw_2030 | AW6: =INDIRECT(csv_selection!$B$1 & csv_selection!$C$1 & "!H63") -> CLaw_perm | AX6: =INDIRECT(csv_selection!$B$1 & csv_selection!$C$1 & "!H64") -> CLaw_perm | AY6: =INDIRECT(csv_selection!$B$1 & csv_selection!$C$1 & "!H65") -> CLaw_perm | AZ6: =INDIRECT(csv_selection!$B$1 & csv_selection!$C$1 & "!H66") -> CLaw_perm | BA6: =INDIRECT(csv_selection!$B$1 & csv_selection!$C$1 & "!H67") -> CLaw_perm | BB6: =INDIRECT(csv_selection!$B$1 & csv_selection!$C$1 & "!H69") -> 0.6327 | BC6: =INDIRECT(csv_selection!$B$1 & csv_selection!$C$1 & "!H70") -> 0.0335 | BD6: =INDIRECT(csv_selection!$B$1 & csv_selection!$C$1 & "!H71") -> 0.3338 | BE6: =INDIRECT(csv_selection!$B$1 & csv_selection!$C$1 & "!H72") -> 0.3941 | BF6: =INDIRECT(csv_selection!$B$1 & csv_selection!$C$1 & "!H73") -> 0.1925 | BG6: =INDIRECT(csv_selection!$B$1 & csv_selection!$C$1 & "!H74") -> 0.4134 | BH6: =INDIRECT(csv_selection!$B$1 & csv_selection!$C$1 & "!H75") -> 1 | BI6: =INDIRECT(csv_selection!$B$1 & csv_selection!$C$1 & "!H76") -> 0 | BJ6: =INDIRECT(csv_selection!$B$1 & csv_selection!$C$1 & "!H77") -> 0 | BK6: =INDIRECT(csv_selection!$B$1 & csv_selection!$C$1 & "!H78") -> 0.6917 | BL6: =INDIRECT(csv_selection!$B$1 & csv_selection!$C$1 & "!H79") -> 0.1284 | BM6: =INDIRECT(csv_selection!$B$1 & csv_selection!$C$1 & "!H80") -> 0.1799 | BN6: =INDIRECT(csv_selection!$B$1 & csv_selection!$C$1 & "!H81") -> 1 | BO6: =INDIRECT(csv_selection!$B$1 & csv_selection!$C$1 & "!H82") -> 0 | BP6: =INDIRECT(csv_selection!$B$1 & csv_selection!$C$1 & "!H83") -> 0 | BQ6: =INDIRECT(csv_selection!$B$1 & csv_selection!$C$1 & "!H84") -> 0.8143 | BR6: =INDIRECT(csv_selection!$B$1 & csv_selection!$C$1 & "!H85") -> 0.0578 | BS6: =INDIRECT(csv_selection!$B$1 & csv_selection!$C$1 & "!H86") -> 0.1279
A7: =INDIRECT(csv_selection!$B$1 & csv_selection!$C$1 & "!I2") -> 2031 | B7: =INDIRECT(csv_selection!$B$1 & csv_selection!$C$1 & "!I5") -> 0.21 | C7: =INDIRECT(csv_selection!$B$1 & csv_selection!$C$1 & "!I6") -> 0.312 | D7: =INDIRECT(csv_selection!$B$1 & csv_selection!$C$1 & "!I7") -> 0.0352 | E7: =INDIRECT(csv_selection!$B$1 & csv_selection!$C$1 & "!I8") -> 0.01 | F7: =INDIRECT(csv_selection!$B$1 & csv_selection!$C$1 & "!I9") -> 0 | G7: =INDIRECT(csv_selection!$B$1 & csv_selection!$C$1 & "!I11") -> 0.2 | H7: =INDIRECT(csv_selection!$B$1 & csv_selection!$C$1 & "!I12") -> 0.3322 | I7: =INDIRECT(csv_selection!$B$1 & csv_selection!$C$1 & "!I13") -> 0.2038 | J7: =INDIRECT(csv_selection!$B$1 & csv_selection!$C$1 & "!I14") -> 0 | K7: =INDIRECT(csv_selection!$B$1 & csv_selection!$C$1 & "!I15") -> 0.3056 | L7: =INDIRECT(csv_selection!$B$1 & csv_selection!$C$1 & "!I16") -> 0.3056 | M7: =INDIRECT(csv_selection!$B$1 & csv_selection!$C$1 & "!I17") -> 0.2341 | N7: =INDIRECT(csv_selection!$B$1 & csv_selection!$C$1 & "!I18") -> 0 | O7: =INDIRECT(csv_selection!$B$1 & csv_selection!$C$1 & "!I20") -> 0.1978 | P7: =INDIRECT(csv_selection!$B$1 & csv_selection!$C$1 & "!I21") -> 0.1814 | Q7: =INDIRECT(csv_selection!$B$1 & csv_selection!$C$1 & "!I23") -> 0.3035 | R7: =INDIRECT(csv_selection!$B$1 & csv_selection!$C$1 & "!I24") -> 0.7744 | S7: =INDIRECT(csv_selection!$B$1 & csv_selection!$C$1 & "!I25") -> 0.9723 | T7: =INDIRECT(csv_selection!$B$1 & csv_selection!$C$1 & "!I26") -> 0.9841 | U7: =INDIRECT(csv_selection!$B$1 & csv_selection!$C$1 & "!I27") -> 0.5723 | V7: =INDIRECT(csv_selection!$B$1 & csv_selection!$C$1 & "!I28") -> 0.0436 | W7: =INDIRECT(csv_selection!$B$1 & csv_selection!$C$1 & "!I31") -> 1 | X7: =INDIRECT(csv_selection!$B$1 & csv_selection!$C$1 & "!I32") -> 1 | Y7: =INDIRECT(csv_selection!$B$1 & csv_selection!$C$1 & "!I33") -> 1 | Z7: =INDIRECT(csv_selection!$B$1 & csv_selection!$C$1 & "!I34") -> 1 | AA7: =INDIRECT(csv_selection!$B$1 & csv_selection!$C$1 & "!I35") -> 1 | AB7: =INDIRECT(csv_selection!$B$1 & csv_selection!$C$1 & "!I36") -> 1 | AC7: =INDIRECT(csv_selection!$B$1 & csv_selection!$C$1 & "!I37") -> 1 | AD7: =INDIRECT(csv_selection!$B$1 & csv_selection!$C$1 & "!I38") -> 1 | AE7: =INDIRECT(csv_selection!$B$1 & csv_selection!$C$1 & "!I40") -> 0 | AF7: =INDIRECT(csv_selection!$B$1 & csv_selection!$C$1 & "!I41") -> 0 | AG7: =INDIRECT(csv_selection!$B$1 & csv_selection!$C$1 & "!I42") -> 0 | AH7: =INDIRECT(csv_selection!$B$1 & csv_selection!$C$1 & "!I43") -> 0 | AI7: =INDIRECT(csv_selection!$B$1 & csv_selection!$C$1 & "!I44") -> 0 | AJ7: =INDIRECT(csv_selection!$B$1 & csv_selection!$C$1 & "!I45") -> 0 | AK7: =INDIRECT(csv_selection!$B$1 & csv_selection!$C$1 & "!I46") -> 0 | AL7: =INDIRECT(csv_selection!$B$1 & csv_selection!$C$1 & "!I47") -> 0 | AM7: =INDIRECT(csv_selection!$B$1 & csv_selection!$C$1 & "!I50") -> CLaw_perm | AN7: =INDIRECT(csv_selection!$B$1 & csv_selection!$C$1 & "!I51") -> CLaw_perm | AO7: =INDIRECT(csv_selection!$B$1 & csv_selection!$C$1 & "!I52") -> CLaw_perm | AP7: =INDIRECT(csv_selection!$B$1 & csv_selection!$C$1 & "!I53") -> CLaw_perm | AQ7: =INDIRECT(csv_selection!$B$1 & csv_selection!$C$1 & "!I54") -> CLCC_perm | AR7: =INDIRECT(csv_selection!$B$1 & csv_selection!$C$1 & "!I55") -> CLPT_perm | AS7: =INDIRECT(csv_selection!$B$1 & csv_selection!$C$1 & "!I56") -> CLaw_perm | AT7: =INDIRECT(csv_selection!$B$1 & csv_selection!$C$1 & "!I58") -> Claw_perm | AU7: =INDIRECT(csv_selection!$B$1 & csv_selection!$C$1 & "!I59") -> CLaw_rduc | AV7: =INDIRECT(csv_selection!$B$1 & csv_selection!$C$1 & "!I61") -> CLaw_2031 | AW7: =INDIRECT(csv_selection!$B$1 & csv_selection!$C$1 & "!I63") -> CLaw_perm | AX7: =INDIRECT(csv_selection!$B$1 & csv_selection!$C$1 & "!I64") -> CLaw_perm | AY7: =INDIRECT(csv_selection!$B$1 & csv_selection!$C$1 & "!I65") -> CLaw_perm | AZ7: =INDIRECT(csv_selection!$B$1 & csv_selection!$C$1 & "!I66") -> CLaw_perm | BA7: =INDIRECT(csv_selection!$B$1 & csv_selection!$C$1 & "!I67") -> CLaw_perm | BB7: =INDIRECT(csv_selection!$B$1 & csv_selection!$C$1 & "!I69") -> 0.6359 | BC7: =INDIRECT(csv_selection!$B$1 & csv_selection!$C$1 & "!I70") -> 0.0335 | BD7: =INDIRECT(csv_selection!$B$1 & csv_selection!$C$1 & "!I71") -> 0.3306 | BE7: =INDIRECT(csv_selection!$B$1 & csv_selection!$C$1 & "!I72") -> 0.3965 | BF7: =INDIRECT(csv_selection!$B$1 & csv_selection!$C$1 & "!I73") -> 0.1925 | BG7: =INDIRECT(csv_selection!$B$1 & csv_selection!$C$1 & "!I74") -> 0.411 | BH7: =INDIRECT(csv_selection!$B$1 & csv_selection!$C$1 & "!I75") -> 1 | BI7: =INDIRECT(csv_selection!$B$1 & csv_selection!$C$1 & "!I76") -> 0 | BJ7: =INDIRECT(csv_selection!$B$1 & csv_selection!$C$1 & "!I77") -> 0 | BK7: =INDIRECT(csv_selection!$B$1 & csv_selection!$C$1 & "!I78") -> 0.6928 | BL7: =INDIRECT(csv_selection!$B$1 & csv_selection!$C$1 & "!I79") -> 0.1284 | BM7: =INDIRECT(csv_selection!$B$1 & csv_selection!$C$1 & "!I80") -> 0.1788 | BN7: =INDIRECT(csv_selection!$B$1 & csv_selection!$C$1 & "!I81") -> 1 | BO7: =INDIRECT(csv_selection!$B$1 & csv_selection!$C$1 & "!I82") -> 0 | BP7: =INDIRECT(csv_selection!$B$1 & csv_selection!$C$1 & "!I83") -> 0 | BQ7: =INDIRECT(csv_selection!$B$1 & csv_selection!$C$1 & "!I84") -> 0.815 | BR7: =INDIRECT(csv_selection!$B$1 & csv_selection!$C$1 & "!I85") -> 0.0578 | BS7: =INDIRECT(csv_selection!$B$1 & csv_selection!$C$1 & "!I86") -> 0.1272
